<?xml version="1.0" ?>
<!-- =================================================================================== -->
<!-- |    This document was autogenerated by xacro from flapping_platform.urdfcopy.xacro | -->
<!-- |    EDITING THIS FILE BY HAND IS NOT RECOMMENDED                                 | -->
<!-- =================================================================================== -->
<robot name="my_robot">
  <link name="arm1_base_link">
    <inertial>
      <origin rpy="0 0 0" xyz="0.000204933302096124 -8.24661684233942E-05 0.0435919339026087"/>
      <mass value="0.604237569846431"/>
      <inertia ixx="0.00082415777403083" ixy="2.9270718368632E-06" ixz="-2.8722520476522E-05" iyy="0.000820579526371655" iyz="2.21535061552891E-06" izz="0.000685679517381249"/>
    </inertial>
    <visual>
      <origin rpy="0 0 0" xyz="0 0 0"/>
      <geometry>
        <mesh filename="file:///home/dushi/flapping_platform_ws/install/flapping_platform_description/share/flapping_platform_description/meshes/rm_63_arm/base_link_III.STL"/>
      </geometry>
      <material name="">
        <color rgba="0.792156862745098 0.819607843137255 0.933333333333333 1"/>
      </material>
    </visual>
    <collision>
      <origin rpy="0 0 0" xyz="0 0 0"/>
      <geometry>
        <mesh filename="file:///home/dushi/flapping_platform_ws/install/flapping_platform_description/share/flapping_platform_description/meshes/rm_63_arm/base_link_III.STL"/>
      </geometry>
    </collision>
  </link>
  <link name="arm1_link1">
    <inertial>
      <origin rpy="0 0 0" xyz="-0.030909 -0.0013023 -0.0053121"/>
      <mass value="1.7668"/>
      <inertia ixx="0.0014534" ixy="-0.00017578" ixz="0.0002802" iyy="0.0043772" iyz="1.7209E-05" izz="0.0040911"/>
    </inertial>
    <visual>
      <origin rpy="0 0 0" xyz="0 0 0"/>
      <geometry>
        <mesh filename="file:///home/dushi/flapping_platform_ws/install/flapping_platform_description/share/flapping_platform_description/meshes/rm_63_arm/link1_III.STL"/>
      </geometry>
      <material name="">
        <color rgba="1 1 1 1"/>
      </material>
    </visual>
    <collision>
      <origin rpy="0 0 0" xyz="0 0 0"/>
      <geometry>
        <mesh filename="file:///home/dushi/flapping_platform_ws/install/flapping_platform_description/share/flapping_platform_description/meshes/rm_63_arm/link1_III.STL"/>
      </geometry>
    </collision>
  </link>
  <joint name="arm1_joint1" type="revolute">
    <origin rpy="0 0 0" xyz="0 0 0.1625"/>
    <parent link="arm1_base_link"/>
    <child link="arm1_link1"/>
    <axis xyz="0 0 1"/>
    <limit effort="100" lower="-3.107" upper="3.107" velocity="1"/>
  </joint>
  <link name="arm1_link2">
    <inertial>
      <origin rpy="0 0 0" xyz="0.16852 9.8217E-07 -0.077258"/>
      <mass value="4.3415"/>
      <inertia ixx="0.0028306" ixy="3.3846E-07" ixz="4.0484E-06" iyy="0.075435" iyz="-3.3974E-08" izz="0.075923"/>
    </inertial>
    <visual>
      <origin rpy="0 0 0" xyz="0 0 0"/>
      <geometry>
        <mesh filename="file:///home/dushi/flapping_platform_ws/install/flapping_platform_description/share/flapping_platform_description/meshes/rm_63_arm/link2.STL"/>
      </geometry>
      <material name="">
        <color rgba="0.86667 0.86667 0.8902 1"/>
      </material>
    </visual>
    <collision>
      <origin rpy="0 0 0" xyz="0 0 0"/>
      <geometry>
        <mesh filename="file:///home/dushi/flapping_platform_ws/install/flapping_platform_description/share/flapping_platform_description/meshes/rm_63_arm/link2.STL"/>
      </geometry>
    </collision>
  </link>
  <joint name="arm1_joint2" type="revolute">
    <origin rpy="-1.5708 -1.5708 0" xyz="-0.086 0 0"/>
    <parent link="arm1_link1"/>
    <child link="arm1_link2"/>
    <axis xyz="0 0 1"/>
    <limit effort="100" lower="-3.107" upper="3.107" velocity="1"/>
  </joint>
  <link name="arm1_link3">
    <inertial>
      <origin rpy="0 0 0" xyz="0.034488 -0.010948 -0.0056239"/>
      <mass value="1.7286"/>
      <inertia ixx="0.0014154" ixy="0.00068025" ixz="-0.00043307" iyy="0.0026049" iyz="0.00017201" izz="0.0028551"/>
    </inertial>
    <visual>
      <origin rpy="0 0 0" xyz="0 0 0"/>
      <geometry>
        <mesh filename="file:///home/dushi/flapping_platform_ws/install/flapping_platform_description/share/flapping_platform_description/meshes/rm_63_arm/link3.STL"/>
      </geometry>
      <material name="">
        <color rgba="0.86667 0.86667 0.8902 1"/>
      </material>
    </visual>
    <collision>
      <origin rpy="0 0 0" xyz="0 0 0"/>
      <geometry>
        <mesh filename="file:///home/dushi/flapping_platform_ws/install/flapping_platform_description/share/flapping_platform_description/meshes/rm_63_arm/link3.STL"/>
      </geometry>
    </collision>
  </link>
  <joint name="arm1_joint3" type="revolute">
    <origin rpy="0 0 1.5708" xyz="0.38 0 0"/>
    <parent link="arm1_link2"/>
    <child link="arm1_link3"/>
    <axis xyz="0 0 1"/>
    <limit effort="100" lower="-3.107" upper="2.531" velocity="1"/>
  </joint>
  <link name="arm1_link4">
    <inertial>
      <origin rpy="0 0 0" xyz="4.1778E-07 -0.030483 -0.19739"/>
      <mass value="2.4734"/>
      <inertia ixx="0.02602" ixy="-1.1659E-07" ixz="3.1323E-07" iyy="0.024375" iyz="0.0061661" izz="0.002958"/>
    </inertial>
    <visual>
      <origin rpy="0 0 0" xyz="0 0 0"/>
      <geometry>
        <mesh filename="file:///home/dushi/flapping_platform_ws/install/flapping_platform_description/share/flapping_platform_description/meshes/rm_63_arm/link4.STL"/>
      </geometry>
      <material name="">
        <color rgba="0.86667 0.86667 0.8902 1"/>
      </material>
    </visual>
    <collision>
      <origin rpy="0 0 0" xyz="0 0 0"/>
      <geometry>
        <mesh filename="file:///home/dushi/flapping_platform_ws/install/flapping_platform_description/share/flapping_platform_description/meshes/rm_63_arm/link4.STL"/>
      </geometry>
    </collision>
  </link>
  <joint name="arm1_joint4" type="revolute">
    <origin rpy="1.5708 0 0" xyz="0.069 -0.405 0"/>
    <parent link="arm1_link3"/>
    <child link="arm1_link4"/>
    <axis xyz="0 0 1"/>
    <limit effort="100" lower="-3.107" upper="3.107" velocity="1"/>
  </joint>
  <link name="arm1_link5">
    <inertial>
      <origin rpy="0 0 0" xyz="5.2596E-06 0.025125 -0.0072574"/>
      <mass value="0.93162"/>
      <inertia ixx="0.0012563" ixy="-1.8115E-08" ixz="-2.4669E-09" iyy="0.0005379" iyz="-0.00017339" izz="0.0011134"/>
    </inertial>
    <visual>
      <origin rpy="0 0 0" xyz="0 0 0"/>
      <geometry>
        <mesh filename="file:///home/dushi/flapping_platform_ws/install/flapping_platform_description/share/flapping_platform_description/meshes/rm_63_arm/link5.STL"/>
      </geometry>
      <material name="">
        <color rgba="0.86667 0.86667 0.8902 1"/>
      </material>
    </visual>
    <collision>
      <origin rpy="0 0 0" xyz="0 0 0"/>
      <geometry>
        <mesh filename="file:///home/dushi/flapping_platform_ws/install/flapping_platform_description/share/flapping_platform_description/meshes/rm_63_arm/link5.STL"/>
      </geometry>
    </collision>
  </link>
  <joint name="arm1_joint5" type="revolute">
    <origin rpy="1.5708 0 3.1416" xyz="0 0 0"/>
    <parent link="arm1_link4"/>
    <child link="arm1_link5"/>
    <axis xyz="0 0 1"/>
    <limit effort="100" lower="-3.107" upper="3.107" velocity="1"/>
  </joint>
  <link name="arm1_link6">
    <inertial>
      <origin rpy="0 0 0" xyz="-3.305E-05 -7.0431E-06 -0.023738"/>
      <mass value="0.3056"/>
      <inertia ixx="0.00011383" ixy="-3.6531E-08" ixz="-1.1422E-07" iyy="0.00011469" iyz="4.3479E-08" izz="0.00012619"/>
    </inertial>
    <visual>
      <origin rpy="0 0 0" xyz="0 0 0"/>
      <geometry>
        <mesh filename="file:///home/dushi/flapping_platform_ws/install/flapping_platform_description/share/flapping_platform_description/meshes/rm_63_arm/link6_6fb.STL"/>
      </geometry>
      <material name="">
        <color rgba="0.86667 0.86667 0.8902 1"/>
      </material>
    </visual>
    <collision>
      <origin rpy="0 0 0" xyz="0 0 0"/>
      <geometry>
        <mesh filename="file:///home/dushi/flapping_platform_ws/install/flapping_platform_description/share/flapping_platform_description/meshes/rm_63_arm/link6_6fb.STL"/>
      </geometry>
    </collision>
  </link>
  <joint name="arm1_joint6" type="revolute">
    <origin rpy="1.5708 0 3.1416" xyz="0 0.1322 0"/>
    <parent link="arm1_link5"/>
    <child link="arm1_link6"/>
    <axis xyz="0 0 -1"/>
    <limit effort="100" lower="-3.14" upper="3.14" velocity="1"/>
  </joint>
  <link name="platform_base_link">
    <inertial>
      <origin rpy="0 0 0" xyz="0 0 0.37288"/>
      <mass value="800.000"/>
      <inertia ixx="165.461018" ixy="0.657490" ixz="0.288120" iyy="166.219920" iyz="-0.498917" izz="125.016291"/>
    </inertial>
    <visual>
      <geometry>
        <mesh filename="file:///home/dushi/flapping_platform_ws/install/flapping_platform_description/share/flapping_platform_description/meshes/platform/base.STL"/>
      </geometry>
      <material name="">
        <color rgba="0.792156862745098 0.819607843137255 0.933333333333333 1"/>
      </material>
    </visual>
  </link>
  <joint name="plate_joint" type="continuous">
    <origin rpy="0 0 0" xyz="0 0 1.15368"/>
    <parent link="platform_base_link"/>
    <child link="platform_plate_Link"/>
    <axis xyz="0 0 1"/>
  </joint>
  <link name="platform_plate_Link">
    <inertial>
      <origin rpy="0 0 0" xyz="0 0 0.04815"/>
      <mass value="200.000"/>
      <inertia ixx="33.295085" ixy="0.000027" ixz="0.000005" iyy="33.295162" iyz="-0.000015" izz="66.259721"/>
    </inertial>
    <visual>
      <geometry>
        <mesh filename="file:///home/dushi/flapping_platform_ws/install/flapping_platform_description/share/flapping_platform_description/meshes/platform/plate.STL"/>
      </geometry>
      <material name="">
        <color rgba="0.792156862745098 0.819607843137255 0.933333333333333 1"/>
      </material>
    </visual>
    <collision>
      <origin rpy="0 0 0" xyz="0 0 0"/>
      <geometry>
        <mesh filename="file:///home/dushi/flapping_platform_ws/install/flapping_platform_description/share/flapping_platform_description/meshes/platform/plate.STL"/>
      </geometry>
    </collision>
  </link>
  <!-- 转台和world连接joint -->
  <link name="world"/>
  <joint name="world_fixed" type="fixed">
    <parent link="world"/>
    <child link="platform_base_link"/>
    <origin rpy="0 0 0" xyz="0 0 0"/>
  </joint>
  <!-- RML63机械臂和转台platform_plate_Link连接joint -->
  <joint name="arm1_body_arm_joint" type="fixed">
    <origin rpy="0 0 3.1415" xyz="1.21704 0 0.095"/>
    <parent link="platform_plate_Link"/>
    <child link="arm1_base_link"/>
    <axis xyz="0 0 0"/>
  </joint>
</robot>
